Workbook

Sheet Calendrier AGO
A1: Semaine | B1: Du | C1: Au | D1: Membre d'astreinte | E1: Membre VD | F1: Feuille de la semaine
A2: 24 | B2: 46181 | C2: 46188 | D2: Laurine Gérard | E2: Adrien | F2: 24
A3: 25 | B3: 46188 | C3: 46195 | D3: Marc-Olivier | E3: Nicolas | F3: 25
A4: 26 | B4: 46195 | C4: 46202 | D4: Steven Troel | E4: Laetitia | F4: 26
A5: 27 | B5: 46202 | C5: 46209 | D5: Flavie Duval | E5: Michel | F5: 27
A6: 28 | B6: 46209 | C6: 46216 | D6: Louise Argaud | E6: Adrien | F6: 28
A7: 29 | B7: 46216 | C7: 46223 | D7: Kevin Robin | E7: Nicolas | F7: 29
A8: 30 | B8: 46223 | C8: 46230 | D8: Marc-Olivier | E8: Laetitia | F8: 30
A9: 31 | B9: 46230 | C9: 46237 | D9: Laurine Gérard | E9: Michel | F9: 31
A10: 32 | B10: 46237 | C10: 46244 | D10: Flavie Duval | E10: Adrien | F10: 32
A11: 33 | B11: 46244 | C11: 46251 | D11: Louise Argaud | E11: Nicolas | F11: 33
A12: 34 | B12: 46251 | C12: 46258 | D12: Steven Troel | E12: Laetitia | F12: 34
A13: 35 | B13: 46258 | C13: 46265 | D13: Nicolas Le Bail | E13: Michel | F13: 35
... A31: 53 | B31: 46384 | C31: 46391 | D31: Flavie Duval | E31: Nicolas | F31: 53

Sheet V
B1: N° de Semaine | J1: Du | N1: Au | V1: Membre AGO | Z1: Membre VD
B2: 23
A4: Antenne | B4: Lundi | F4: Mardi | J4: Mercredi | N4: Jeudi | R4: Vendredi | V4: Samedi | Z4: Dimanche
B5: DPS | C5: Inscript. | F5: DPS | G5: Inscript. | J5: DPS | K5: Inscript. | N5: DPS | O5: Inscript. | R5: DPS | S5: Inscript. | V5: DPS | W5: Inscript. | Z5: DPS | AA5: Inscript.
C6: Nb | D6: De | E6: Tl | G6: Nb | H6: De | I6: Tl | K6: Nb | L6: De | M6: Tl | O6: Nb | P6: De | Q6: Tl | S6: Nb | T6: De | U6: Tl | W6: Nb | X6: De | Y6: Tl | AA6: Nb | AB6: De | AC6: Tl
A7: LNP (Lannion)
A10: PDG (Guingamp)
A13: PPL (Paimpol)
A16: STB (Saint Brieuc)
A19: PLR (Plérin)
A22: LPP (Lamballe)
A25: BRC (Broons)
A28: PDN (Dinan)
A31: QTN (Quintin)
A34: LCB (Loudeac)
A37: 22 (Siège)
A42: Indicatif | B42: Antenne | F42: Remarques | G42: Lundi | K42: Mardi | O42: Mercredi | S42: Jeudi | W42: Vendredi | AE42: Samedi | AG42: Dimanche
A44: VPSP1 Lannion | B44: LNP (Lannion) | C44: 1 LOT A
A45: PSM1 Lannion | C45: 1 LOT A + 1 C
A46: VTU-TP1 Lannion | C46: 1 LOT A + 1 C
A47: VL2 Lannion | C47: 1 LOT A + 1 C
A48: VLHR Lannion
A49: VPSP XX | B49: Paimpol (PPL)
A51: VPSP Vally | B51: PDG (Guingamp) | C51: 1 LOT A
A52: VL PABU
A53: VTP LANRODEC | C53: 1 LOT A + 1 C
A54: VPSP GOUEDIC | B54: STB (Saint Brieuc) | C54: 1 LOT A
A55: PSMA GRIFFON | C55: 1 LOT A + 1 C
A56: VPSP Rohanne'ch | B56: PLR (Plérin) | C56: 1 LOT A
A57: PSMA Guilloux | C57: 1 LOT A + 1 C
A58: VPSP 1 LAMBALLE | B58: LPP (Lamballe) | C58: 1 LOT A
A59: VTU-TP GRIFFON | C59: 1 LOT A + 1 C
A60: VTP CENTAURE
A61: VPSP X | B61: BRC (Broons) | C61: 1 LOT A
A63: VPSP 1 SAINT SAUVEUR | B63: PDN (Dinan) | C63: 1 LOT A
A65: VPSP XXX | B65: QTN (Quintin)
A67: VTUTP Loudeac | B67: LCB (Loudeac) | C67: 1 LOT A
A69: VPSP Samu | B69: 22 (Siège) | C69: 1 LOT A
A70: VPSP Armor | C70: 1 LOT A
A71: VPSP Le Braz
...

Sheet 24
B1: N° de Semaine | D1: Du | E1: Au | G1: Membre AGO | I1: Membre VD
B2: 24 | D2: 08/06/2026 | E2: 14/06/2026 | G2: Laurine Gérard | I2: Adrien LEBRETON
A4: Antenne | B4: Lundi | C4: Mardi | D4: Mercredi | E4: Jeudi | F4: Vendredi | H4: Samedi | J4: Dimanche
F5: DPS | G5: IS | H5: DPS | I5: IS | J5: DPS | K5: IS
A6: LNP (Lannion) | H6: 4 - Aquarantec | I6: 46116 | J6: 4 - Au fil de l'eau | K6: 46116
H7: 4 - Marmouzeries d'été | I7: 46114
A9: PDG (Guingamp) | H9: 4 - Summer Palet Fest | I9: 46116
H10: 6 - Journée des débutants | I10: 46178
A12: PPL (Paimpol) | E12: 2 - Vers l'emploi Rugby | F12: 4 - Inauguration guinguette | G12: 46116 | H12: 4 - Corrida de Langueux part.2 | I12: 23/29
A15: STB (Saint Brieuc) | F15: 4 - Inauguration guinguette | G15: 46116 | H15: 8 - La nordique Corrida de Langueux part.1 | I15: 46242
F16: 11 - La Run In Baie Corrida de Langueux | G16: 46337 | H16: 16 - Corrida de Langueux part.2 | I16: 23/29
A18: PLR (Plérin) | E18: 2 - Vers l'emploi Rugby | F18: 11 - La Run In Baie Corrida de Langueux | G18: 46337 | H18: 8 - La nordique Corrida de Langueux part.1 | I18: 46242
H19: 16 - Corrida de Langueux part.2 | I19: 23/29
A21: LPP (Lamballe) | H21: 4 - Festival de musique | I21: 46116
A24: PDN (Dinan) | F24: 11 - La Run In Baie Corrida de Langueux | G24: 46337 | H24: 4 - Créa dance | I24: 46116
H25: 15 - Corrida de Langueux part.2 | I25: 23/29
A27: BRC (Broons)
A30: QTN (Quintin) | H30: 6 - Journée des débutants | I30: 46178
A33: LCB (Loudeac) | F33: 4 - Tournoi international Guerledan | G33: 46116 | H33: 6 - Journée des débutants | I33: 46178
A36: 22 (Siège) | F36: 4 - Tournoi international Guerledan | G36: 46116 | H36: 8 - La nordique Corrida de Langueux part.1 | I36: 46242
F37: 11 - La Run In Baie Corrida de Langueux | G37: 46337 | H37: 29 - Corrida de Langueux part.2 | I37: 23/29
A41: Indicatif | B41: Antenne | C41: Lot de Secours | D41: Lundi | E41: Mardi | F41: Mercredi | G41: Jeudi | H41: Vendredi | J41: Samedi | L41: Dimanche
A43: VPSP1 Lannion | B43: LNP (Lannion) | C43: 1 LOT A | D43: INDISPO | E43: INDISPO | F43: INDISPO | G43: INDISPO | H43: INDISPO | J43: INDISPO | K43: INDISPO | L43: INDISPO | M43: INDISPO
A44: PSM1 Lannion | C44: 1 LOT A + 1 C | J44: Marmouzeries d'été
A45: VTU-TP1 Lannion | C45: 1 LOT A + 1 C
A46: VL2 Lannion
A47: VL-C8 | H47: Guinguette | J47: Cérémonie
A48: VLHR Lannion
B49: Paimpol (PPL)
A51: VPSP Vally | B51: PDG (Guingamp) | C51: 1 LOT A | J51: Summer Palet Fest
A52: VL PABU
A53: VTP LANRODEC | C53: 1 LOT A + 1 C
A54: VPSP GOUEDIC | B54: STB (Saint Brieuc) | C54: 1 LOT A | J54: Corrida 1 et 2 | K54: Corrida de Langueux
A55: PSMA GRIFFON | C55: 1 LOT A + 1 C | H55: Guinguette | J55: Cadets - Dons
A56: VPSP Rohanne'ch | B56: PLR (Plérin) | C56: 1 LOT A | G56: Vers l'emploi Rugby | J56: Corrida 1 et 2 | K56: Corrida de Langueux
A57: PSMA Guilloux | C57: 1 LOT A + 1 C
A58: VPSP 1 LAMBALLE | B58: LPP (Lamballe) | C58: 1 LOT A
A59: VTU-TP GRIFFON | C59: 1 LOT A + 1 C | J59: Festival de musique
A60: VTP CENTAURE | J60: Journée des débutants
A61: VPSP 1 SAINT SAUVEUR | B61: PDN (Dinan) | C61: 1 LOT A | K61: Créa Dance
...

Sheet 25
B1: N° de Semaine | J1: Du | N1: Au | V1: Membre AGO | Z1: Membre VD
B2: ='Calendrier AGO'!A3 -> 25 | J2: ='Calendrier AGO'!B3 -> 46188 | N2: ='Calendrier AGO'!C3 -> 46195 | V2: ='Calendrier AGO'!D3 -> Marc-Olivier | Z2: ='Calendrier AGO'!E3 -> Nicolas
A4: Antenne | B4: Lundi | F4: Mardi | J4: Mercredi | N4: Jeudi | R4: Vendredi | V4: Samedi | Z4: Dimanche
B5: DPS | C5: Inscript. | F5: DPS | G5: Inscript. | J5: DPS | K5: Inscript. | N5: DPS | O5: Inscript. | R5: DPS | S5: Inscript. | V5: DPS | W5: Inscript. | Z5: DPS | AA5: Inscript.
C6: Nb | D6: De | E6: Tl | G6: Nb | H6: De | I6: Tl | K6: Nb | L6: De | M6: Tl | O6: Nb | P6: De | Q6: Tl | S6: Nb | T6: De | U6: Tl | W6: Nb | X6: De | Y6: Tl | AA6: Nb | AB6: De | AC6: Tl
A7: LNP (Lannion)
A10: PDG (Guingamp)
A13: PPL (Paimpol)
A16: STB (Saint Brieuc)
A19: PLR (Plérin)
A22: LPP (Lamballe)
A25: BRC (Broons)
A28: PDN (Dinan)
A31: QTN (Quintin)
A34: LCB (Loudeac)
A37: 22 (Siège)
A42: Indicatif | B42: Antenne | F42: Remarques | G42: Lundi | K42: Mardi | O42: Mercredi | S42: Jeudi | W42: Vendredi | AE42: Samedi | AG42: Dimanche
A44: VPSP1 Lannion | B44: LNP (Lannion) | C44: 1 LOT A
A45: PSM1 Lannion | C45: 1 LOT A + 1 C
A46: VTU-TP1 Lannion | C46: 1 LOT A + 1 C
A47: VL2 Lannion | C47: 1 LOT A + 1 C
A48: VLHR Lannion
A49: VPSP XX | B49: Paimpol (PPL)
A51: VPSP Vally | B51: PDG (Guingamp) | C51: 1 LOT A
A52: VL PABU
A53: VTP LANRODEC | C53: 1 LOT A + 1 C
A54: VPSP GOUEDIC | B54: STB (Saint Brieuc) | C54: 1 LOT A
A55: PSMA GRIFFON | C55: 1 LOT A + 1 C
A56: VPSP Rohanne'ch | B56: PLR (Plérin) | C56: 1 LOT A
A57: PSMA Guilloux | C57: 1 LOT A + 1 C
A58: VPSP 1 LAMBALLE | B58: LPP (Lamballe) | C58: 1 LOT A
A59: VTU-TP GRIFFON | C59: 1 LOT A + 1 C
A60: VTP CENTAURE
A61: VPSP X | B61: BRC (Broons) | C61: 1 LOT A
A63: VPSP 1 SAINT SAUVEUR | B63: PDN (Dinan) | C63: 1 LOT A
A65: VPSP XXX | B65: QTN (Quintin)
A67: VTUTP Loudeac | B67: LCB (Loudeac) | C67: 1 LOT A
A69: VPSP Samu | B69: 22 (Siège) | C69: 1 LOT A
A70: VPSP Armor | C70: 1 LOT A
A71: VPSP Le Braz
...

Sheet 26
B1: N° de Semaine | J1: Du | N1: Au | V1: Membre AGO | Z1: Membre VD
B2: ='Calendrier AGO'!A4 -> 26 | J2: ='Calendrier AGO'!B4 -> 46195 | N2: ='Calendrier AGO'!C4 -> 46202 | V2: ='Calendrier AGO'!D4 -> Steven Troel | Z2: ='Calendrier AGO'!E4 -> Laetitia
A4: Antenne | B4: Lundi | F4: Mardi | J4: Mercredi | N4: Jeudi | R4: Vendredi | V4: Samedi | Z4: Dimanche
B5: DPS | C5: Inscript. | F5: DPS | G5: Inscript. | J5: DPS | K5: Inscript. | N5: DPS | O5: Inscript. | R5: DPS | S5: Inscript. | V5: DPS | W5: Inscript. | Z5: DPS | AA5: Inscript.
C6: Nb | D6: De | E6: Tl | G6: Nb | H6: De | I6: Tl | K6: Nb | L6: De | M6: Tl | O6: Nb | P6: De | Q6: Tl | S6: Nb | T6: De | U6: Tl | W6: Nb | X6: De | Y6: Tl | AA6: Nb | AB6: De | AC6: Tl
A7: LNP (Lannion) | R7: PAPS - Festival Chants de Choral (14h15-15h40) | U7: 2 | V7: DPS-PE Bégard en Cavale (18h00-21h30) | W7: 6 | Y7: 5 | Z7: PAPS - Festival Chants de Choral (16h45-18h00) | AC7: 2
R8: PAPS - Festival Chants de Choral (18h45-20h20) | U8: 2 | V8: PAPS - Festival Chants de Choral (18h30-23h00) | Y8: 2 | Z8: PAPS - Festival Chants de Choral (18h15-19h00) | AC8: 2
A10: PDG (Guingamp) | V10: DPS-PE Solidarité PLB Muco (08h00-17h30) | W10: 8 | Y10: 6
V11: DPS-PE Le Festin'Loc (18h00-02h00) | W11: 5 | Y11: 4
A13: PPL (Paimpol) | R13: DPS-PE Paimpol In Rock (17h00-01h00) | S13: 4 | U13: 4 | V13: DPS-PE Paimpol In Rock (14h00-01h00) | W13: 5 | Y13: 6
A16: STB (Saint Brieuc) | V16: PAPS - Rencontre des équipes (12h00-17h00) | W16: 2 | Y16: 2
A19: PLR (Plérin) | Z19: DPS-PE Beach Rugby (09h30-17h00) | AA19: 2 | AC19: 4
A22: LPP (Lamballe)
A25: BRC (Broons) | Z25: DPS-PE Trail Raid FFTri (11h00-18h00) | AC25: 5
A28: PDN (Dinan) | Z28: DPS-PE Trail des deux Ponts (07h00-12h30) | AA28: 4 | AC28: 6
A31: QTN (Quintin)
A34: LCB (Loudeac)
A37: 22 (Siège) | F37: DPS-PE Open de Golf (08h00-20h00) | I37: 5 | J37: DPS-PE Open de Golf (08h00-20h00) | K37: 2 | M37: 5 | N37: DPS-PE Open de Golf (08h00-20h00) | Q37: 5 | R37: DPS-PE Open de Golf (08h00-20h00) | U37: 5 | V37: DPS-PE Open de Golf (08h00-20h00) | Y37: 5 | Z37: DPS-PE Guerledan à la nage (08h00-18h00) | AC37: 4
N38: Plastons exercice | O38: 21 | Q38: 20 | V38: DPS-PE Open de Golf (18h00-02h00) | Y38: 7 | Z38: DPS-PE T24 Breizh (07h00-13h00) | AC38: 5
V39: DPS-PE T24 Breizh (13h00-00h00) | Y39: 5
V40: DPS-PE T24 Breizh (23h00-08h00) | Y40: 5
A43: Indicatif | B43: Antenne | F43: Remarques | G43: Lundi | K43: Mardi | O43: Mercredi | S43: Jeudi | W43: Vendredi | AE43: Samedi | AG43: Dimanche
A45: VPSP1 Lannion | B45: LNP (Lannion) | C45: 1 LOT A
A46: PSM1 Lannion | C46: 1 LOT A + 1 C
A47: VTU-TP1 Lannion | C47: 1 LOT A + 1 C
A48: VL2 Lannion | C48: 1 LOT A + 1 C
A49: VLHR Lannion
A50: VPSP XX | B50: Paimpol (PPL)
A52: VPSP Vally | B52: PDG (Guingamp) | C52: 1 LOT A
A53: VL PABU
A54: VTP LANRODEC | C54: 1 LOT A + 1 C
A55: VPSP GOUEDIC | B55: STB (Saint Brieuc) | C55: 1 LOT A
A56: PSMA GRIFFON | C56: 1 LOT A + 1 C
A57: VPSP Rohanne'ch | B57: PLR (Plérin) | C57: 1 LOT A
A58: PSMA Guilloux | C58: 1 LOT A + 1 C
A59: VPSP 1 LAMBALLE | B59: LPP (Lamballe) | C59: 1 LOT A
A60: VTU-TP GRIFFON | C60: 1 LOT A + 1 C
A61: VTP CENTAURE
A62: VPSP X | B62: BRC (Broons) | C62: 1 LOT A
A64: VPSP 1 SAINT SAUVEUR | B64: PDN (Dinan) | C64: 1 LOT A
...

Sheet 27
B1: N° de Semaine | J1: Du | N1: Au | V1: Membre AGO | Z1: Membre VD
B2: ='Calendrier AGO'!A5 -> 27 | J2: ='Calendrier AGO'!B5 -> 46202 | N2: ='Calendrier AGO'!C5 -> 46209 | V2: ='Calendrier AGO'!D5 -> Flavie Duval | Z2: ='Calendrier AGO'!E5 -> Michel
A4: Antenne | B4: Lundi | F4: Mardi | J4: Mercredi | N4: Jeudi | R4: Vendredi | V4: Samedi | Z4: Dimanche
B5: DPS | C5: Inscript. | F5: DPS | G5: Inscript. | J5: DPS | K5: Inscript. | N5: DPS | O5: Inscript. | R5: DPS | S5: Inscript. | V5: DPS | W5: Inscript. | Z5: DPS | AA5: Inscript.
C6: Nb | D6: De | E6: Tl | G6: Nb | H6: De | I6: Tl | K6: Nb | L6: De | M6: Tl | O6: Nb | P6: De | Q6: Tl | S6: Nb | T6: De | U6: Tl | W6: Nb | X6: De | Y6: Tl | AA6: Nb | AB6: De | AC6: Tl
A7: LNP (Lannion)
A10: PDG (Guingamp)
A13: PPL (Paimpol)
A16: STB (Saint Brieuc)
A19: PLR (Plérin)
A22: LPP (Lamballe)
A25: BRC (Broons)
A28: PDN (Dinan)
A31: QTN (Quintin)
A34: LCB (Loudeac)
A37: 22 (Siège)
A42: Indicatif | B42: Antenne | F42: Remarques | G42: Lundi | K42: Mardi | O42: Mercredi | S42: Jeudi | W42: Vendredi | AE42: Samedi | AG42: Dimanche
A44: VPSP1 Lannion | B44: LNP (Lannion) | C44: 1 LOT A
A45: PSM1 Lannion | C45: 1 LOT A + 1 C
A46: VTU-TP1 Lannion | C46: 1 LOT A + 1 C
A47: VL2 Lannion | C47: 1 LOT A + 1 C
A48: VLHR Lannion
A49: VPSP XX | B49: Paimpol (PPL)
A51: VPSP Vally | B51: PDG (Guingamp) | C51: 1 LOT A
A52: VL PABU
A53: VTP LANRODEC | C53: 1 LOT A + 1 C
A54: VPSP GOUEDIC | B54: STB (Saint Brieuc) | C54: 1 LOT A
A55: PSMA GRIFFON | C55: 1 LOT A + 1 C
A56: VPSP Rohanne'ch | B56: PLR (Plérin) | C56: 1 LOT A
A57: PSMA Guilloux | C57: 1 LOT A + 1 C
A58: VPSP 1 LAMBALLE | B58: LPP (Lamballe) | C58: 1 LOT A
A59: VTU-TP GRIFFON | C59: 1 LOT A + 1 C
A60: VTP CENTAURE
A61: VPSP X | B61: BRC (Broons) | C61: 1 LOT A
A63: VPSP 1 SAINT SAUVEUR | B63: PDN (Dinan) | C63: 1 LOT A
A65: VPSP XXX | B65: QTN (Quintin)
A67: VTUTP Loudeac | B67: LCB (Loudeac) | C67: 1 LOT A
A69: VPSP Samu | B69: 22 (Siège) | C69: 1 LOT A
A70: VPSP Armor | C70: 1 LOT A
A71: VPSP Le Braz
...

Sheet 28
B1: N° de Semaine | J1: Du | N1: Au | V1: Membre AGO | Z1: Membre VD
B2: ='Calendrier AGO'!A6 -> 28 | J2: ='Calendrier AGO'!B6 -> 46209 | N2: ='Calendrier AGO'!C6 -> 46216 | V2: ='Calendrier AGO'!D6 -> Louise Argaud | Z2: ='Calendrier AGO'!E6 -> Adrien
A4: Antenne | B4: Lundi | F4: Mardi | J4: Mercredi | N4: Jeudi | R4: Vendredi | V4: Samedi | Z4: Dimanche
B5: DPS | C5: Inscript. | F5: DPS | G5: Inscript. | J5: DPS | K5: Inscript. | N5: DPS | O5: Inscript. | R5: DPS | S5: Inscript. | V5: DPS | W5: Inscript. | Z5: DPS | AA5: Inscript.
C6: Nb | D6: De | E6: Tl | G6: Nb | H6: De | I6: Tl | K6: Nb | L6: De | M6: Tl | O6: Nb | P6: De | Q6: Tl | S6: Nb | T6: De | U6: Tl | W6: Nb | X6: De | Y6: Tl | AA6: Nb | AB6: De | AC6: Tl
A7: LNP (Lannion)
A10: PDG (Guingamp)
A13: PPL (Paimpol)
A16: STB (Saint Brieuc)
A19: PLR (Plérin)
A22: LPP (Lamballe)
A25: BRC (Broons)
A28: PDN (Dinan)
A31: QTN (Quintin)
A34: LCB (Loudeac)
A37: 22 (Siège)
A42: Indicatif | B42: Antenne | F42: Remarques | G42: Lundi | K42: Mardi | O42: Mercredi | S42: Jeudi | W42: Vendredi | AE42: Samedi | AG42: Dimanche
A44: VPSP1 Lannion | B44: LNP (Lannion) | C44: 1 LOT A
A45: PSM1 Lannion | C45: 1 LOT A + 1 C
A46: VTU-TP1 Lannion | C46: 1 LOT A + 1 C
A47: VL2 Lannion | C47: 1 LOT A + 1 C
A48: VLHR Lannion
A49: VPSP XX | B49: Paimpol (PPL)
A51: VPSP Vally | B51: PDG (Guingamp) | C51: 1 LOT A
A52: VL PABU
A53: VTP LANRODEC | C53: 1 LOT A + 1 C
A54: VPSP GOUEDIC | B54: STB (Saint Brieuc) | C54: 1 LOT A
A55: PSMA GRIFFON | C55: 1 LOT A + 1 C
A56: VPSP Rohanne'ch | B56: PLR (Plérin) | C56: 1 LOT A
A57: PSMA Guilloux | C57: 1 LOT A + 1 C
A58: VPSP 1 LAMBALLE | B58: LPP (Lamballe) | C58: 1 LOT A
A59: VTU-TP GRIFFON | C59: 1 LOT A + 1 C
A60: VTP CENTAURE
A61: VPSP X | B61: BRC (Broons) | C61: 1 LOT A
A63: VPSP 1 SAINT SAUVEUR | B63: PDN (Dinan) | C63: 1 LOT A
A65: VPSP XXX | B65: QTN (Quintin)
A67: VTUTP Loudeac | B67: LCB (Loudeac) | C67: 1 LOT A
A69: VPSP Samu | B69: 22 (Siège) | C69: 1 LOT A
A70: VPSP Armor | C70: 1 LOT A
A71: VPSP Le Braz
...

Sheet 29
B1: N° de Semaine | J1: Du | N1: Au | V1: Membre AGO | Z1: Membre VD
B2: ='Calendrier AGO'!A7 -> 29 | J2: ='Calendrier AGO'!B7 -> 46216 | N2: ='Calendrier AGO'!C7 -> 46223 | V2: ='Calendrier AGO'!D7 -> Kevin Robin | Z2: ='Calendrier AGO'!E7 -> Nicolas
A4: Antenne | B4: Lundi | F4: Mardi | J4: Mercredi | N4: Jeudi | R4: Vendredi | V4: Samedi | Z4: Dimanche
B5: DPS | C5: Inscript. | F5: DPS | G5: Inscript. | J5: DPS | K5: Inscript. | N5: DPS | O5: Inscript. | R5: DPS | S5: Inscript. | V5: DPS | W5: Inscript. | Z5: DPS | AA5: Inscript.
C6: Nb | D6: De | E6: Tl | G6: Nb | H6: De | I6: Tl | K6: Nb | L6: De | M6: Tl | O6: Nb | P6: De | Q6: Tl | S6: Nb | T6: De | U6: Tl | W6: Nb | X6: De | Y6: Tl | AA6: Nb | AB6: De | AC6: Tl
A7: LNP (Lannion)
A10: PDG (Guingamp)
A13: PPL (Paimpol)
A16: STB (Saint Brieuc)
A19: PLR (Plérin)
A22: LPP (Lamballe)
A25: BRC (Broons)
A28: PDN (Dinan)
A31: QTN (Quintin)
A34: LCB (Loudeac)
A37: 22 (Siège)
A42: Indicatif | B42: Antenne | F42: Remarques | G42: Lundi | K42: Mardi | O42: Mercredi | S42: Jeudi | W42: Vendredi | AE42: Samedi | AG42: Dimanche
A44: VPSP1 Lannion | B44: LNP (Lannion) | C44: 1 LOT A
A45: PSM1 Lannion | C45: 1 LOT A + 1 C
A46: VTU-TP1 Lannion | C46: 1 LOT A + 1 C
A47: VL2 Lannion | C47: 1 LOT A + 1 C
A48: VLHR Lannion
A49: VPSP XX | B49: Paimpol (PPL)
A51: VPSP Vally | B51: PDG (Guingamp) | C51: 1 LOT A
A52: VL PABU
A53: VTP LANRODEC | C53: 1 LOT A + 1 C
A54: VPSP GOUEDIC | B54: STB (Saint Brieuc) | C54: 1 LOT A
A55: PSMA GRIFFON | C55: 1 LOT A + 1 C
A56: VPSP Rohanne'ch | B56: PLR (Plérin) | C56: 1 LOT A
A57: PSMA Guilloux | C57: 1 LOT A + 1 C
A58: VPSP 1 LAMBALLE | B58: LPP (Lamballe) | C58: 1 LOT A
A59: VTU-TP GRIFFON | C59: 1 LOT A + 1 C
A60: VTP CENTAURE
A61: VPSP X | B61: BRC (Broons) | C61: 1 LOT A
A63: VPSP 1 SAINT SAUVEUR | B63: PDN (Dinan) | C63: 1 LOT A
A65: VPSP XXX | B65: QTN (Quintin)
A67: VTUTP Loudeac | B67: LCB (Loudeac) | C67: 1 LOT A
A69: VPSP Samu | B69: 22 (Siège) | C69: 1 LOT A
A70: VPSP Armor | C70: 1 LOT A
A71: VPSP Le Braz
...

Sheet 30
B1: N° de Semaine | J1: Du | N1: Au | V1: Membre AGO | Z1: Membre VD
B2: ='Calendrier AGO'!A8 -> 30 | J2: ='Calendrier AGO'!B8 -> 46223 | N2: ='Calendrier AGO'!C8 -> 46230 | V2: ='Calendrier AGO'!D8 -> Marc-Olivier | Z2: ='Calendrier AGO'!E8 -> Laetitia
A4: Antenne | B4: Lundi | F4: Mardi | J4: Mercredi | N4: Jeudi | R4: Vendredi | V4: Samedi | Z4: Dimanche
B5: DPS | C5: Inscript. | F5: DPS | G5: Inscript. | J5: DPS | K5: Inscript. | N5: DPS | O5: Inscript. | R5: DPS | S5: Inscript. | V5: DPS | W5: Inscript. | Z5: DPS | AA5: Inscript.
C6: Nb | D6: De | E6: Tl | G6: Nb | H6: De | I6: Tl | K6: Nb | L6: De | M6: Tl | O6: Nb | P6: De | Q6: Tl | S6: Nb | T6: De | U6: Tl | W6: Nb | X6: De | Y6: Tl | AA6: Nb | AB6: De | AC6: Tl
A7: LNP (Lannion)
A10: PDG (Guingamp)
A13: PPL (Paimpol)
A16: STB (Saint Brieuc)
A19: PLR (Plérin)
A22: LPP (Lamballe)
A25: BRC (Broons)
A28: PDN (Dinan)
A31: QTN (Quintin)
A34: LCB (Loudeac)
A37: 22 (Siège)
A42: Indicatif | B42: Antenne | F42: Remarques | G42: Lundi | K42: Mardi | O42: Mercredi | S42: Jeudi | W42: Vendredi | AE42: Samedi | AG42: Dimanche
A44: VPSP1 Lannion | B44: LNP (Lannion) | C44: 1 LOT A
A45: PSM1 Lannion | C45: 1 LOT A + 1 C
A46: VTU-TP1 Lannion | C46: 1 LOT A + 1 C
A47: VL2 Lannion | C47: 1 LOT A + 1 C
A48: VLHR Lannion
A49: VPSP XX | B49: Paimpol (PPL)
A51: VPSP Vally | B51: PDG (Guingamp) | C51: 1 LOT A
A52: VL PABU
A53: VTP LANRODEC | C53: 1 LOT A + 1 C
A54: VPSP GOUEDIC | B54: STB (Saint Brieuc) | C54: 1 LOT A
A55: PSMA GRIFFON | C55: 1 LOT A + 1 C
A56: VPSP Rohanne'ch | B56: PLR (Plérin) | C56: 1 LOT A
A57: PSMA Guilloux | C57: 1 LOT A + 1 C
A58: VPSP 1 LAMBALLE | B58: LPP (Lamballe) | C58: 1 LOT A
A59: VTU-TP GRIFFON | C59: 1 LOT A + 1 C
A60: VTP CENTAURE
A61: VPSP X | B61: BRC (Broons) | C61: 1 LOT A
A63: VPSP 1 SAINT SAUVEUR | B63: PDN (Dinan) | C63: 1 LOT A
A65: VPSP XXX | B65: QTN (Quintin)
A67: VTUTP Loudeac | B67: LCB (Loudeac) | C67: 1 LOT A
A69: VPSP Samu | B69: 22 (Siège) | C69: 1 LOT A
A70: VPSP Armor | C70: 1 LOT A
A71: VPSP Le Braz
...

Sheet 31
B1: N° de Semaine | J1: Du | N1: Au | V1: Membre AGO | Z1: Membre VD
B2: ='Calendrier AGO'!A9 -> 31 | J2: ='Calendrier AGO'!B9 -> 46230 | N2: ='Calendrier AGO'!C9 -> 46237 | V2: ='Calendrier AGO'!D9 -> Laurine Gérard | Z2: ='Calendrier AGO'!E9 -> Michel
A4: Antenne | B4: Lundi | F4: Mardi | J4: Mercredi | N4: Jeudi | R4: Vendredi | V4: Samedi | Z4: Dimanche
B5: DPS | C5: Inscript. | F5: DPS | G5: Inscript. | J5: DPS | K5: Inscript. | N5: DPS | O5: Inscript. | R5: DPS | S5: Inscript. | V5: DPS | W5: Inscript. | Z5: DPS | AA5: Inscript.
C6: Nb | D6: De | E6: Tl | G6: Nb | H6: De | I6: Tl | K6: Nb | L6: De | M6: Tl | O6: Nb | P6: De | Q6: Tl | S6: Nb | T6: De | U6: Tl | W6: Nb | X6: De | Y6: Tl | AA6: Nb | AB6: De | AC6: Tl
A7: LNP (Lannion)
A10: PDG (Guingamp)
A13: PPL (Paimpol)
A16: STB (Saint Brieuc)
A19: PLR (Plérin)
A22: LPP (Lamballe)
A25: BRC (Broons)
A28: PDN (Dinan)
A31: QTN (Quintin)
A34: LCB (Loudeac)
A37: 22 (Siège)
A42: Indicatif | B42: Antenne | F42: Remarques | G42: Lundi | K42: Mardi | O42: Mercredi | S42: Jeudi | W42: Vendredi | AE42: Samedi | AG42: Dimanche
A44: VPSP1 Lannion | B44: LNP (Lannion) | C44: 1 LOT A
A45: PSM1 Lannion | C45: 1 LOT A + 1 C
A46: VTU-TP1 Lannion | C46: 1 LOT A + 1 C
A47: VL2 Lannion | C47: 1 LOT A + 1 C
A48: VLHR Lannion
A49: VPSP XX | B49: Paimpol (PPL)
A51: VPSP Vally | B51: PDG (Guingamp) | C51: 1 LOT A
A52: VL PABU
A53: VTP LANRODEC | C53: 1 LOT A + 1 C
A54: VPSP GOUEDIC | B54: STB (Saint Brieuc) | C54: 1 LOT A
A55: PSMA GRIFFON | C55: 1 LOT A + 1 C
A56: VPSP Rohanne'ch | B56: PLR (Plérin) | C56: 1 LOT A
A57: PSMA Guilloux | C57: 1 LOT A + 1 C
A58: VPSP 1 LAMBALLE | B58: LPP (Lamballe) | C58: 1 LOT A
A59: VTU-TP GRIFFON | C59: 1 LOT A + 1 C
A60: VTP CENTAURE
A61: VPSP X | B61: BRC (Broons) | C61: 1 LOT A
A63: VPSP 1 SAINT SAUVEUR | B63: PDN (Dinan) | C63: 1 LOT A
A65: VPSP XXX | B65: QTN (Quintin)
A67: VTUTP Loudeac | B67: LCB (Loudeac) | C67: 1 LOT A
A69: VPSP Samu | B69: 22 (Siège) | C69: 1 LOT A
A70: VPSP Armor | C70: 1 LOT A
A71: VPSP Le Braz
...

Sheet 32
B1: N° de Semaine | J1: Du | N1: Au | V1: Membre AGO | Z1: Membre VD
B2: ='Calendrier AGO'!A10 -> 32 | J2: ='Calendrier AGO'!B10 -> 46237 | N2: ='Calendrier AGO'!C10 -> 46244 | V2: ='Calendrier AGO'!D10 -> Flavie Duval | Z2: ='Calendrier AGO'!E10 -> Adrien
A4: Antenne | B4: Lundi | F4: Mardi | J4: Mercredi | N4: Jeudi | R4: Vendredi | V4: Samedi | Z4: Dimanche
B5: DPS | C5: Inscript. | F5: DPS | G5: Inscript. | J5: DPS | K5: Inscript. | N5: DPS | O5: Inscript. | R5: DPS | S5: Inscript. | V5: DPS | W5: Inscript. | Z5: DPS | AA5: Inscript.
C6: Nb | D6: De | E6: Tl | G6: Nb | H6: De | I6: Tl | K6: Nb | L6: De | M6: Tl | O6: Nb | P6: De | Q6: Tl | S6: Nb | T6: De | U6: Tl | W6: Nb | X6: De | Y6: Tl | AA6: Nb | AB6: De | AC6: Tl
A7: LNP (Lannion)
A10: PDG (Guingamp)
A13: PPL (Paimpol)
A16: STB (Saint Brieuc)
A19: PLR (Plérin)
A22: LPP (Lamballe)
A25: BRC (Broons)
A28: PDN (Dinan)
A31: QTN (Quintin)
A34: LCB (Loudeac)
A37: 22 (Siège)
A42: Indicatif | B42: Antenne | F42: Remarques | G42: Lundi | K42: Mardi | O42: Mercredi | S42: Jeudi | W42: Vendredi | AE42: Samedi | AG42: Dimanche
A44: VPSP1 Lannion | B44: LNP (Lannion) | C44: 1 LOT A
A45: PSM1 Lannion | C45: 1 LOT A + 1 C
A46: VTU-TP1 Lannion | C46: 1 LOT A + 1 C
A47: VL2 Lannion | C47: 1 LOT A + 1 C
A48: VLHR Lannion
A49: VPSP XX | B49: Paimpol (PPL)
A51: VPSP Vally | B51: PDG (Guingamp) | C51: 1 LOT A
A52: VL PABU
A53: VTP LANRODEC | C53: 1 LOT A + 1 C
A54: VPSP GOUEDIC | B54: STB (Saint Brieuc) | C54: 1 LOT A
A55: PSMA GRIFFON | C55: 1 LOT A + 1 C
A56: VPSP Rohanne'ch | B56: PLR (Plérin) | C56: 1 LOT A
A57: PSMA Guilloux | C57: 1 LOT A + 1 C
A58: VPSP 1 LAMBALLE | B58: LPP (Lamballe) | C58: 1 LOT A
A59: VTU-TP GRIFFON | C59: 1 LOT A + 1 C
A60: VTP CENTAURE
A61: VPSP X | B61: BRC (Broons) | C61: 1 LOT A
A63: VPSP 1 SAINT SAUVEUR | B63: PDN (Dinan) | C63: 1 LOT A
A65: VPSP XXX | B65: QTN (Quintin)
A67: VTUTP Loudeac | B67: LCB (Loudeac) | C67: 1 LOT A
A69: VPSP Samu | B69: 22 (Siège) | C69: 1 LOT A
A70: VPSP Armor | C70: 1 LOT A
A71: VPSP Le Braz
...

Sheet 33
B1: N° de Semaine | J1: Du | N1: Au | V1: Membre AGO | Z1: Membre VD
B2: ='Calendrier AGO'!A11 -> 33 | J2: ='Calendrier AGO'!B11 -> 46244 | N2: ='Calendrier AGO'!C11 -> 46251 | V2: ='Calendrier AGO'!D11 -> Louise Argaud | Z2: ='Calendrier AGO'!E11 -> Nicolas
A4: Antenne | B4: Lundi | F4: Mardi | J4: Mercredi | N4: Jeudi | R4: Vendredi | V4: Samedi | Z4: Dimanche
B5: DPS | C5: Inscript. | F5: DPS | G5: Inscript. | J5: DPS | K5: Inscript. | N5: DPS | O5: Inscript. | R5: DPS | S5: Inscript. | V5: DPS | W5: Inscript. | Z5: DPS | AA5: Inscript.
C6: Nb | D6: De | E6: Tl | G6: Nb | H6: De | I6: Tl | K6: Nb | L6: De | M6: Tl | O6: Nb | P6: De | Q6: Tl | S6: Nb | T6: De | U6: Tl | W6: Nb | X6: De | Y6: Tl | AA6: Nb | AB6: De | AC6: Tl
A7: LNP (Lannion)
A10: PDG (Guingamp)
A13: PPL (Paimpol)
A16: STB (Saint Brieuc)
A19: PLR (Plérin)
A22: LPP (Lamballe)
A25: BRC (Broons)
A28: PDN (Dinan)
A31: QTN (Quintin)
A34: LCB (Loudeac)
A37: 22 (Siège)
A42: Indicatif | B42: Antenne | F42: Remarques | G42: Lundi | K42: Mardi | O42: Mercredi | S42: Jeudi | W42: Vendredi | AE42: Samedi | AG42: Dimanche
A44: VPSP1 Lannion | B44: LNP (Lannion) | C44: 1 LOT A
A45: PSM1 Lannion | C45: 1 LOT A + 1 C
A46: VTU-TP1 Lannion | C46: 1 LOT A + 1 C
A47: VL2 Lannion | C47: 1 LOT A + 1 C
A48: VLHR Lannion
A49: VPSP XX | B49: Paimpol (PPL)
A51: VPSP Vally | B51: PDG (Guingamp) | C51: 1 LOT A
A52: VL PABU
A53: VTP LANRODEC | C53: 1 LOT A + 1 C
A54: VPSP GOUEDIC | B54: STB (Saint Brieuc) | C54: 1 LOT A
A55: PSMA GRIFFON | C55: 1 LOT A + 1 C
A56: VPSP Rohanne'ch | B56: PLR (Plérin) | C56: 1 LOT A
A57: PSMA Guilloux | C57: 1 LOT A + 1 C
A58: VPSP 1 LAMBALLE | B58: LPP (Lamballe) | C58: 1 LOT A
A59: VTU-TP GRIFFON | C59: 1 LOT A + 1 C
A60: VTP CENTAURE
A61: VPSP X | B61: BRC (Broons) | C61: 1 LOT A
A63: VPSP 1 SAINT SAUVEUR | B63: PDN (Dinan) | C63: 1 LOT A
A65: VPSP XXX | B65: QTN (Quintin)
A67: VTUTP Loudeac | B67: LCB (Loudeac) | C67: 1 LOT A
A69: VPSP Samu | B69: 22 (Siège) | C69: 1 LOT A
A70: VPSP Armor | C70: 1 LOT A
A71: VPSP Le Braz
...

Sheet 34
B1: N° de Semaine | J1: Du | N1: Au | V1: Membre AGO | Z1: Membre VD
B2: ='Calendrier AGO'!A12 -> 34 | J2: ='Calendrier AGO'!B12 -> 46251 | N2: ='Calendrier AGO'!C12 -> 46258 | V2: ='Calendrier AGO'!D12 -> Steven Troel | Z2: ='Calendrier AGO'!E12 -> Laetitia
A4: Antenne | B4: Lundi | F4: Mardi | J4: Mercredi | N4: Jeudi | R4: Vendredi | V4: Samedi | Z4: Dimanche
B5: DPS | C5: Inscript. | F5: DPS | G5: Inscript. | J5: DPS | K5: Inscript. | N5: DPS | O5: Inscript. | R5: DPS | S5: Inscript. | V5: DPS | W5: Inscript. | Z5: DPS | AA5: Inscript.
C6: Nb | D6: De | E6: Tl | G6: Nb | H6: De | I6: Tl | K6: Nb | L6: De | M6: Tl | O6: Nb | P6: De | Q6: Tl | S6: Nb | T6: De | U6: Tl | W6: Nb | X6: De | Y6: Tl | AA6: Nb | AB6: De | AC6: Tl
A7: LNP (Lannion)
A10: PDG (Guingamp)
A13: PPL (Paimpol)
A16: STB (Saint Brieuc)
A19: PLR (Plérin)
A22: LPP (Lamballe)
A25: BRC (Broons)
A28: PDN (Dinan)
A31: QTN (Quintin)
A34: LCB (Loudeac)
A37: 22 (Siège)
A42: Indicatif | B42: Antenne | F42: Remarques | G42: Lundi | K42: Mardi | O42: Mercredi | S42: Jeudi | W42: Vendredi | AE42: Samedi | AG42: Dimanche
A44: VPSP1 Lannion | B44: LNP (Lannion) | C44: 1 LOT A
A45: PSM1 Lannion | C45: 1 LOT A + 1 C
A46: VTU-TP1 Lannion | C46: 1 LOT A + 1 C
A47: VL2 Lannion | C47: 1 LOT A + 1 C
A48: VLHR Lannion
A49: VPSP XX | B49: Paimpol (PPL)
A51: VPSP Vally | B51: PDG (Guingamp) | C51: 1 LOT A
A52: VL PABU
A53: VTP LANRODEC | C53: 1 LOT A + 1 C
A54: VPSP GOUEDIC | B54: STB (Saint Brieuc) | C54: 1 LOT A
A55: PSMA GRIFFON | C55: 1 LOT A + 1 C
A56: VPSP Rohanne'ch | B56: PLR (Plérin) | C56: 1 LOT A
A57: PSMA Guilloux | C57: 1 LOT A + 1 C
A58: VPSP 1 LAMBALLE | B58: LPP (Lamballe) | C58: 1 LOT A
A59: VTU-TP GRIFFON | C59: 1 LOT A + 1 C
A60: VTP CENTAURE
A61: VPSP X | B61: BRC (Broons) | C61: 1 LOT A
A63: VPSP 1 SAINT SAUVEUR | B63: PDN (Dinan) | C63: 1 LOT A
A65: VPSP XXX | B65: QTN (Quintin)
A67: VTUTP Loudeac | B67: LCB (Loudeac) | C67: 1 LOT A
A69: VPSP Samu | B69: 22 (Siège) | C69: 1 LOT A
A70: VPSP Armor | C70: 1 LOT A
A71: VPSP Le Braz
...

Sheet 35
B1: N° de Semaine | J1: Du | N1: Au | V1: Membre AGO | Z1: Membre VD
B2: ='Calendrier AGO'!A13 -> 35 | J2: ='Calendrier AGO'!B13 -> 46258 | N2: ='Calendrier AGO'!C13 -> 46265 | V2: ='Calendrier AGO'!D13 -> Nicolas Le Bail | Z2: ='Calendrier AGO'!E13 -> Michel
A4: Antenne | B4: Lundi | F4: Mardi | J4: Mercredi | N4: Jeudi | R4: Vendredi | V4: Samedi | Z4: Dimanche
B5: DPS | C5: Inscript. | F5: DPS | G5: Inscript. | J5: DPS | K5: Inscript. | N5: DPS | O5: Inscript. | R5: DPS | S5: Inscript. | V5: DPS | W5: Inscript. | Z5: DPS | AA5: Inscript.
C6: Nb | D6: De | E6: Tl | G6: Nb | H6: De | I6: Tl | K6: Nb | L6: De | M6: Tl | O6: Nb | P6: De | Q6: Tl | S6: Nb | T6: De | U6: Tl | W6: Nb | X6: De | Y6: Tl | AA6: Nb | AB6: De | AC6: Tl
A7: LNP (Lannion)
A10: PDG (Guingamp)
A13: PPL (Paimpol)
A16: STB (Saint Brieuc)
A19: PLR (Plérin)
A22: LPP (Lamballe)
A25: BRC (Broons)
A28: PDN (Dinan)
A31: QTN (Quintin)
A34: LCB (Loudeac)
A37: 22 (Siège)
A42: Indicatif | B42: Antenne | F42: Remarques | G42: Lundi | K42: Mardi | O42: Mercredi | S42: Jeudi | W42: Vendredi | AE42: Samedi | AG42: Dimanche
A44: VPSP1 Lannion | B44: LNP (Lannion) | C44: 1 LOT A
A45: PSM1 Lannion | C45: 1 LOT A + 1 C
A46: VTU-TP1 Lannion | C46: 1 LOT A + 1 C
A47: VL2 Lannion | C47: 1 LOT A + 1 C
A48: VLHR Lannion
A49: VPSP XX | B49: Paimpol (PPL)
A51: VPSP Vally | B51: PDG (Guingamp) | C51: 1 LOT A
A52: VL PABU
A53: VTP LANRODEC | C53: 1 LOT A + 1 C
A54: VPSP GOUEDIC | B54: STB (Saint Brieuc) | C54: 1 LOT A
A55: PSMA GRIFFON | C55: 1 LOT A + 1 C
A56: VPSP Rohanne'ch | B56: PLR (Plérin) | C56: 1 LOT A
A57: PSMA Guilloux | C57: 1 LOT A + 1 C
A58: VPSP 1 LAMBALLE | B58: LPP (Lamballe) | C58: 1 LOT A
A59: VTU-TP GRIFFON | C59: 1 LOT A + 1 C
A60: VTP CENTAURE
A61: VPSP X | B61: BRC (Broons) | C61: 1 LOT A
A63: VPSP 1 SAINT SAUVEUR | B63: PDN (Dinan) | C63: 1 LOT A
A65: VPSP XXX | B65: QTN (Quintin)
A67: VTUTP Loudeac | B67: LCB (Loudeac) | C67: 1 LOT A
A69: VPSP Samu | B69: 22 (Siège) | C69: 1 LOT A
A70: VPSP Armor | C70: 1 LOT A
A71: VPSP Le Braz
...

Sheet 36
B1: N° de Semaine | J1: Du | N1: Au | V1: Membre AGO | Z1: Membre VD
B2: ='Calendrier AGO'!A14 -> 36 | J2: ='Calendrier AGO'!B14 -> 46265 | N2: ='Calendrier AGO'!C14 -> 46272 | V2: ='Calendrier AGO'!D14 -> Kevin Robin | Z2: ='Calendrier AGO'!E14 -> Adrien
A4: Antenne | B4: Lundi | F4: Mardi | J4: Mercredi | N4: Jeudi | R4: Vendredi | V4: Samedi | Z4: Dimanche
B5: DPS | C5: Inscript. | F5: DPS | G5: Inscript. | J5: DPS | K5: Inscript. | N5: DPS | O5: Inscript. | R5: DPS | S5: Inscript. | V5: DPS | W5: Inscript. | Z5: DPS | AA5: Inscript.
C6: Nb | D6: De | E6: Tl | G6: Nb | H6: De | I6: Tl | K6: Nb | L6: De | M6: Tl | O6: Nb | P6: De | Q6: Tl | S6: Nb | T6: De | U6: Tl | W6: Nb | X6: De | Y6: Tl | AA6: Nb | AB6: De | AC6: Tl
A7: LNP (Lannion)
A10: PDG (Guingamp)
A13: PPL (Paimpol)
A16: STB (Saint Brieuc)
A19: PLR (Plérin)
A22: LPP (Lamballe)
A25: BRC (Broons)
A28: PDN (Dinan)
A31: QTN (Quintin)
A34: LCB (Loudeac)
A37: 22 (Siège)
A42: Indicatif | B42: Antenne | F42: Remarques | G42: Lundi | K42: Mardi | O42: Mercredi | S42: Jeudi | W42: Vendredi | AE42: Samedi | AG42: Dimanche
A44: VPSP1 Lannion | B44: LNP (Lannion) | C44: 1 LOT A
A45: PSM1 Lannion | C45: 1 LOT A + 1 C
A46: VTU-TP1 Lannion | C46: 1 LOT A + 1 C
A47: VL2 Lannion | C47: 1 LOT A + 1 C
A48: VLHR Lannion
A49: VPSP XX | B49: Paimpol (PPL)
A51: VPSP Vally | B51: PDG (Guingamp) | C51: 1 LOT A
A52: VL PABU
A53: VTP LANRODEC | C53: 1 LOT A + 1 C
A54: VPSP GOUEDIC | B54: STB (Saint Brieuc) | C54: 1 LOT A
A55: PSMA GRIFFON | C55: 1 LOT A + 1 C
A56: VPSP Rohanne'ch | B56: PLR (Plérin) | C56: 1 LOT A
A57: PSMA Guilloux | C57: 1 LOT A + 1 C
A58: VPSP 1 LAMBALLE | B58: LPP (Lamballe) | C58: 1 LOT A
A59: VTU-TP GRIFFON | C59: 1 LOT A + 1 C
A60: VTP CENTAURE
A61: VPSP X | B61: BRC (Broons) | C61: 1 LOT A
A63: VPSP 1 SAINT SAUVEUR | B63: PDN (Dinan) | C63: 1 LOT A
A65: VPSP XXX | B65: QTN (Quintin)
A67: VTUTP Loudeac | B67: LCB (Loudeac) | C67: 1 LOT A
A69: VPSP Samu | B69: 22 (Siège) | C69: 1 LOT A
A70: VPSP Armor | C70: 1 LOT A
A71: VPSP Le Braz
...

Sheet 37
B1: N° de Semaine | J1: Du | N1: Au | V1: Membre AGO | Z1: Membre VD
B2: ='Calendrier AGO'!A15 -> 37 | J2: ='Calendrier AGO'!B15 -> 46272 | N2: ='Calendrier AGO'!C15 -> 46279 | V2: ='Calendrier AGO'!D15 -> Marc-Olivier | Z2: ='Calendrier AGO'!E15 -> Nicolas
A4: Antenne | B4: Lundi | F4: Mardi | J4: Mercredi | N4: Jeudi | R4: Vendredi | V4: Samedi | Z4: Dimanche
B5: DPS | C5: Inscript. | F5: DPS | G5: Inscript. | J5: DPS | K5: Inscript. | N5: DPS | O5: Inscript. | R5: DPS | S5: Inscript. | V5: DPS | W5: Inscript. | Z5: DPS | AA5: Inscript.
C6: Nb | D6: De | E6: Tl | G6: Nb | H6: De | I6: Tl | K6: Nb | L6: De | M6: Tl | O6: Nb | P6: De | Q6: Tl | S6: Nb | T6: De | U6: Tl | W6: Nb | X6: De | Y6: Tl | AA6: Nb | AB6: De | AC6: Tl
A7: LNP (Lannion)
A10: PDG (Guingamp)
A13: PPL (Paimpol)
A16: STB (Saint Brieuc)
A19: PLR (Plérin)
A22: LPP (Lamballe)
A25: BRC (Broons)
A28: PDN (Dinan)
A31: QTN (Quintin)
A34: LCB (Loudeac)
A37: 22 (Siège)
A42: Indicatif | B42: Antenne | F42: Remarques | G42: Lundi | K42: Mardi | O42: Mercredi | S42: Jeudi | W42: Vendredi | AE42: Samedi | AG42: Dimanche
A44: VPSP1 Lannion | B44: LNP (Lannion) | C44: 1 LOT A
A45: PSM1 Lannion | C45: 1 LOT A + 1 C
A46: VTU-TP1 Lannion | C46: 1 LOT A + 1 C
A47: VL2 Lannion | C47: 1 LOT A + 1 C
A48: VLHR Lannion
A49: VPSP XX | B49: Paimpol (PPL)
A51: VPSP Vally | B51: PDG (Guingamp) | C51: 1 LOT A
A52: VL PABU
A53: VTP LANRODEC | C53: 1 LOT A + 1 C
A54: VPSP GOUEDIC | B54: STB (Saint Brieuc) | C54: 1 LOT A
A55: PSMA GRIFFON | C55: 1 LOT A + 1 C
A56: VPSP Rohanne'ch | B56: PLR (Plérin) | C56: 1 LOT A
A57: PSMA Guilloux | C57: 1 LOT A + 1 C
A58: VPSP 1 LAMBALLE | B58: LPP (Lamballe) | C58: 1 LOT A
A59: VTU-TP GRIFFON | C59: 1 LOT A + 1 C
A60: VTP CENTAURE
A61: VPSP X | B61: BRC (Broons) | C61: 1 LOT A
A63: VPSP 1 SAINT SAUVEUR | B63: PDN (Dinan) | C63: 1 LOT A
A65: VPSP XXX | B65: QTN (Quintin)
A67: VTUTP Loudeac | B67: LCB (Loudeac) | C67: 1 LOT A
A69: VPSP Samu | B69: 22 (Siège) | C69: 1 LOT A
A70: VPSP Armor | C70: 1 LOT A
A71: VPSP Le Braz
...

Sheet 38
B1: N° de Semaine | J1: Du | N1: Au | V1: Membre AGO | Z1: Membre VD
B2: ='Calendrier AGO'!A16 -> 38 | J2: ='Calendrier AGO'!B16 -> 46279 | N2: ='Calendrier AGO'!C16 -> 46286 | V2: ='Calendrier AGO'!D16 -> Laurine Gérard | Z2: ='Calendrier AGO'!E16 -> Laetitia
A4: Antenne | B4: Lundi | F4: Mardi | J4: Mercredi | N4: Jeudi | R4: Vendredi | V4: Samedi | Z4: Dimanche
B5: DPS | C5: Inscript. | F5: DPS | G5: Inscript. | J5: DPS | K5: Inscript. | N5: DPS | O5: Inscript. | R5: DPS | S5: Inscript. | V5: DPS | W5: Inscript. | Z5: DPS | AA5: Inscript.
C6: Nb | D6: De | E6: Tl | G6: Nb | H6: De | I6: Tl | K6: Nb | L6: De | M6: Tl | O6: Nb | P6: De | Q6: Tl | S6: Nb | T6: De | U6: Tl | W6: Nb | X6: De | Y6: Tl | AA6: Nb | AB6: De | AC6: Tl
A7: LNP (Lannion)
A10: PDG (Guingamp)
A13: PPL (Paimpol)
A16: STB (Saint Brieuc)
A19: PLR (Plérin)
A22: LPP (Lamballe)
A25: BRC (Broons)
A28: PDN (Dinan)
A31: QTN (Quintin)
A34: LCB (Loudeac)
A37: 22 (Siège)
A42: Indicatif | B42: Antenne | F42: Remarques | G42: Lundi | K42: Mardi | O42: Mercredi | S42: Jeudi | W42: Vendredi | AE42: Samedi | AG42: Dimanche
A44: VPSP1 Lannion | B44: LNP (Lannion) | C44: 1 LOT A
A45: PSM1 Lannion | C45: 1 LOT A + 1 C
A46: VTU-TP1 Lannion | C46: 1 LOT A + 1 C
A47: VL2 Lannion | C47: 1 LOT A + 1 C
A48: VLHR Lannion
A49: VPSP XX | B49: Paimpol (PPL)
A51: VPSP Vally | B51: PDG (Guingamp) | C51: 1 LOT A
A52: VL PABU
A53: VTP LANRODEC | C53: 1 LOT A + 1 C
A54: VPSP GOUEDIC | B54: STB (Saint Brieuc) | C54: 1 LOT A
A55: PSMA GRIFFON | C55: 1 LOT A + 1 C
A56: VPSP Rohanne'ch | B56: PLR (Plérin) | C56: 1 LOT A
A57: PSMA Guilloux | C57: 1 LOT A + 1 C
A58: VPSP 1 LAMBALLE | B58: LPP (Lamballe) | C58: 1 LOT A
A59: VTU-TP GRIFFON | C59: 1 LOT A + 1 C
A60: VTP CENTAURE
A61: VPSP X | B61: BRC (Broons) | C61: 1 LOT A
A63: VPSP 1 SAINT SAUVEUR | B63: PDN (Dinan) | C63: 1 LOT A
A65: VPSP XXX | B65: QTN (Quintin)
A67: VTUTP Loudeac | B67: LCB (Loudeac) | C67: 1 LOT A
A69: VPSP Samu | B69: 22 (Siège) | C69: 1 LOT A
A70: VPSP Armor | C70: 1 LOT A
A71: VPSP Le Braz
...

Sheet 39
B1: N° de Semaine | J1: Du | N1: Au | V1: Membre AGO | Z1: Membre VD
B2: ='Calendrier AGO'!A17 -> 39 | J2: ='Calendrier AGO'!B17 -> 46286 | N2: ='Calendrier AGO'!C17 -> 46293 | V2: ='Calendrier AGO'!D17 -> Flavie Duval | Z2: ='Calendrier AGO'!E17 -> Michel
A4: Antenne | B4: Lundi | F4: Mardi | J4: Mercredi | N4: Jeudi | R4: Vendredi | V4: Samedi | Z4: Dimanche
B5: DPS | C5: Inscript. | F5: DPS | G5: Inscript. | J5: DPS | K5: Inscript. | N5: DPS | O5: Inscript. | R5: DPS | S5: Inscript. | V5: DPS | W5: Inscript. | Z5: DPS | AA5: Inscript.
C6: Nb | D6: De | E6: Tl | G6: Nb | H6: De | I6: Tl | K6: Nb | L6: De | M6: Tl | O6: Nb | P6: De | Q6: Tl | S6: Nb | T6: De | U6: Tl | W6: Nb | X6: De | Y6: Tl | AA6: Nb | AB6: De | AC6: Tl
A7: LNP (Lannion)
A10: PDG (Guingamp)
A13: PPL (Paimpol)
A16: STB (Saint Brieuc)
A19: PLR (Plérin)
A22: LPP (Lamballe)
A25: BRC (Broons)
A28: PDN (Dinan)
A31: QTN (Quintin)
A34: LCB (Loudeac)
A37: 22 (Siège)
A42: Indicatif | B42: Antenne | F42: Remarques | G42: Lundi | K42: Mardi | O42: Mercredi | S42: Jeudi | W42: Vendredi | AE42: Samedi | AG42: Dimanche
A44: VPSP1 Lannion | B44: LNP (Lannion) | C44: 1 LOT A
A45: PSM1 Lannion | C45: 1 LOT A + 1 C
A46: VTU-TP1 Lannion | C46: 1 LOT A + 1 C
A47: VL2 Lannion | C47: 1 LOT A + 1 C
A48: VLHR Lannion
A49: VPSP XX | B49: Paimpol (PPL)
A51: VPSP Vally | B51: PDG (Guingamp) | C51: 1 LOT A
A52: VL PABU
A53: VTP LANRODEC | C53: 1 LOT A + 1 C
A54: VPSP GOUEDIC | B54: STB (Saint Brieuc) | C54: 1 LOT A
A55: PSMA GRIFFON | C55: 1 LOT A + 1 C
A56: VPSP Rohanne'ch | B56: PLR (Plérin) | C56: 1 LOT A
A57: PSMA Guilloux | C57: 1 LOT A + 1 C
A58: VPSP 1 LAMBALLE | B58: LPP (Lamballe) | C58: 1 LOT A
A59: VTU-TP GRIFFON | C59: 1 LOT A + 1 C
A60: VTP CENTAURE
A61: VPSP X | B61: BRC (Broons) | C61: 1 LOT A
A63: VPSP 1 SAINT SAUVEUR | B63: PDN (Dinan) | C63: 1 LOT A
A65: VPSP XXX | B65: QTN (Quintin)
A67: VTUTP Loudeac | B67: LCB (Loudeac) | C67: 1 LOT A
A69: VPSP Samu | B69: 22 (Siège) | C69: 1 LOT A
A70: VPSP Armor | C70: 1 LOT A
A71: VPSP Le Braz
...

Sheet 40
B1: N° de Semaine | J1: Du | N1: Au | V1: Membre AGO | Z1: Membre VD
B2: ='Calendrier AGO'!A18 -> 40 | J2: ='Calendrier AGO'!B18 -> 46293 | N2: ='Calendrier AGO'!C18 -> 46300 | V2: ='Calendrier AGO'!D18 -> Steven Troel | Z2: ='Calendrier AGO'!E18 -> Adrien
A4: Antenne | B4: Lundi | F4: Mardi | J4: Mercredi | N4: Jeudi | R4: Vendredi | V4: Samedi | Z4: Dimanche
B5: DPS | C5: Inscript. | F5: DPS | G5: Inscript. | J5: DPS | K5: Inscript. | N5: DPS | O5: Inscript. | R5: DPS | S5: Inscript. | V5: DPS | W5: Inscript. | Z5: DPS | AA5: Inscript.
C6: Nb | D6: De | E6: Tl | G6: Nb | H6: De | I6: Tl | K6: Nb | L6: De | M6: Tl | O6: Nb | P6: De | Q6: Tl | S6: Nb | T6: De | U6: Tl | W6: Nb | X6: De | Y6: Tl | AA6: Nb | AB6: De | AC6: Tl
A7: LNP (Lannion)
A10: PDG (Guingamp)
A13: PPL (Paimpol)
A16: STB (Saint Brieuc)
A19: PLR (Plérin)
A22: LPP (Lamballe)
A25: BRC (Broons)
A28: PDN (Dinan)
A31: QTN (Quintin)
A34: LCB (Loudeac)
A37: 22 (Siège)
A42: Indicatif | B42: Antenne | F42: Remarques | G42: Lundi | K42: Mardi | O42: Mercredi | S42: Jeudi | W42: Vendredi | AE42: Samedi | AG42: Dimanche
A44: VPSP1 Lannion | B44: LNP (Lannion) | C44: 1 LOT A
A45: PSM1 Lannion | C45: 1 LOT A + 1 C
A46: VTU-TP1 Lannion | C46: 1 LOT A + 1 C
A47: VL2 Lannion | C47: 1 LOT A + 1 C
A48: VLHR Lannion
A49: VPSP XX | B49: Paimpol (PPL)
A51: VPSP Vally | B51: PDG (Guingamp) | C51: 1 LOT A
A52: VL PABU
A53: VTP LANRODEC | C53: 1 LOT A + 1 C
A54: VPSP GOUEDIC | B54: STB (Saint Brieuc) | C54: 1 LOT A
A55: PSMA GRIFFON | C55: 1 LOT A + 1 C
A56: VPSP Rohanne'ch | B56: PLR (Plérin) | C56: 1 LOT A
A57: PSMA Guilloux | C57: 1 LOT A + 1 C
A58: VPSP 1 LAMBALLE | B58: LPP (Lamballe) | C58: 1 LOT A
A59: VTU-TP GRIFFON | C59: 1 LOT A + 1 C
A60: VTP CENTAURE
A61: VPSP X | B61: BRC (Broons) | C61: 1 LOT A
A63: VPSP 1 SAINT SAUVEUR | B63: PDN (Dinan) | C63: 1 LOT A
A65: VPSP XXX | B65: QTN (Quintin)
A67: VTUTP Loudeac | B67: LCB (Loudeac) | C67: 1 LOT A
A69: VPSP Samu | B69: 22 (Siège) | C69: 1 LOT A
A70: VPSP Armor | C70: 1 LOT A
A71: VPSP Le Braz
...

Sheet 41
B1: N° de Semaine | J1: Du | N1: Au | V1: Membre AGO | Z1: Membre VD
B2: ='Calendrier AGO'!A19 -> 41 | J2: ='Calendrier AGO'!B19 -> 46300 | N2: ='Calendrier AGO'!C19 -> 46307 | V2: ='Calendrier AGO'!D19 -> Louise Argaud | Z2: ='Calendrier AGO'!E19 -> Nicolas
A4: Antenne | B4: Lundi | F4: Mardi | J4: Mercredi | N4: Jeudi | R4: Vendredi | V4: Samedi | Z4: Dimanche
B5: DPS | C5: Inscript. | F5: DPS | G5: Inscript. | J5: DPS | K5: Inscript. | N5: DPS | O5: Inscript. | R5: DPS | S5: Inscript. | V5: DPS | W5: Inscript. | Z5: DPS | AA5: Inscript.
C6: Nb | D6: De | E6: Tl | G6: Nb | H6: De | I6: Tl | K6: Nb | L6: De | M6: Tl | O6: Nb | P6: De | Q6: Tl | S6: Nb | T6: De | U6: Tl | W6: Nb | X6: De | Y6: Tl | AA6: Nb | AB6: De | AC6: Tl
A7: LNP (Lannion)
A10: PDG (Guingamp)
A13: PPL (Paimpol)
A16: STB (Saint Brieuc)
A19: PLR (Plérin)
A22: LPP (Lamballe)
A25: BRC (Broons)
A28: PDN (Dinan)
A31: QTN (Quintin)
A34: LCB (Loudeac)
A37: 22 (Siège)
A42: Indicatif | B42: Antenne | F42: Remarques | G42: Lundi | K42: Mardi | O42: Mercredi | S42: Jeudi | W42: Vendredi | AE42: Samedi | AG42: Dimanche
A44: VPSP1 Lannion | B44: LNP (Lannion) | C44: 1 LOT A
A45: PSM1 Lannion | C45: 1 LOT A + 1 C
A46: VTU-TP1 Lannion | C46: 1 LOT A + 1 C
A47: VL2 Lannion | C47: 1 LOT A + 1 C
A48: VLHR Lannion
A49: VPSP XX | B49: Paimpol (PPL)
A51: VPSP Vally | B51: PDG (Guingamp) | C51: 1 LOT A
A52: VL PABU
A53: VTP LANRODEC | C53: 1 LOT A + 1 C
A54: VPSP GOUEDIC | B54: STB (Saint Brieuc) | C54: 1 LOT A
A55: PSMA GRIFFON | C55: 1 LOT A + 1 C
A56: VPSP Rohanne'ch | B56: PLR (Plérin) | C56: 1 LOT A
A57: PSMA Guilloux | C57: 1 LOT A + 1 C
A58: VPSP 1 LAMBALLE | B58: LPP (Lamballe) | C58: 1 LOT A
A59: VTU-TP GRIFFON | C59: 1 LOT A + 1 C
A60: VTP CENTAURE
A61: VPSP X | B61: BRC (Broons) | C61: 1 LOT A
A63: VPSP 1 SAINT SAUVEUR | B63: PDN (Dinan) | C63: 1 LOT A
A65: VPSP XXX | B65: QTN (Quintin)
A67: VTUTP Loudeac | B67: LCB (Loudeac) | C67: 1 LOT A
A69: VPSP Samu | B69: 22 (Siège) | C69: 1 LOT A
A70: VPSP Armor | C70: 1 LOT A
A71: VPSP Le Braz
...

Sheet 42
B1: N° de Semaine | J1: Du | N1: Au | V1: Membre AGO | Z1: Membre VD
B2: ='Calendrier AGO'!A20 -> 42 | J2: ='Calendrier AGO'!B20 -> 46307 | N2: ='Calendrier AGO'!C20 -> 46314 | V2: ='Calendrier AGO'!D20 -> Nicolas Le Bail | Z2: ='Calendrier AGO'!E20 -> Laetitia
A4: Antenne | B4: Lundi | F4: Mardi | J4: Mercredi | N4: Jeudi | R4: Vendredi | V4: Samedi | Z4: Dimanche
B5: DPS | C5: Inscript. | F5: DPS | G5: Inscript. | J5: DPS | K5: Inscript. | N5: DPS | O5: Inscript. | R5: DPS | S5: Inscript. | V5: DPS | W5: Inscript. | Z5: DPS | AA5: Inscript.
C6: Nb | D6: De | E6: Tl | G6: Nb | H6: De | I6: Tl | K6: Nb | L6: De | M6: Tl | O6: Nb | P6: De | Q6: Tl | S6: Nb | T6: De | U6: Tl | W6: Nb | X6: De | Y6: Tl | AA6: Nb | AB6: De | AC6: Tl
A7: LNP (Lannion)
A10: PDG (Guingamp)
A13: PPL (Paimpol)
A16: STB (Saint Brieuc)
A19: PLR (Plérin)
A22: LPP (Lamballe)
A25: BRC (Broons)
A28: PDN (Dinan)
A31: QTN (Quintin)
A34: LCB (Loudeac)
A37: 22 (Siège)
A42: Indicatif | B42: Antenne | F42: Remarques | G42: Lundi | K42: Mardi | O42: Mercredi | S42: Jeudi | W42: Vendredi | AE42: Samedi | AG42: Dimanche
A44: VPSP1 Lannion | B44: LNP (Lannion) | C44: 1 LOT A
A45: PSM1 Lannion | C45: 1 LOT A + 1 C
A46: VTU-TP1 Lannion | C46: 1 LOT A + 1 C
A47: VL2 Lannion | C47: 1 LOT A + 1 C
A48: VLHR Lannion
A49: VPSP XX | B49: Paimpol (PPL)
A51: VPSP Vally | B51: PDG (Guingamp) | C51: 1 LOT A
A52: VL PABU
A53: VTP LANRODEC | C53: 1 LOT A + 1 C
A54: VPSP GOUEDIC | B54: STB (Saint Brieuc) | C54: 1 LOT A
A55: PSMA GRIFFON | C55: 1 LOT A + 1 C
A56: VPSP Rohanne'ch | B56: PLR (Plérin) | C56: 1 LOT A
A57: PSMA Guilloux | C57: 1 LOT A + 1 C
A58: VPSP 1 LAMBALLE | B58: LPP (Lamballe) | C58: 1 LOT A
A59: VTU-TP GRIFFON | C59: 1 LOT A + 1 C
A60: VTP CENTAURE
A61: VPSP X | B61: BRC (Broons) | C61: 1 LOT A
A63: VPSP 1 SAINT SAUVEUR | B63: PDN (Dinan) | C63: 1 LOT A
A65: VPSP XXX | B65: QTN (Quintin)
A67: VTUTP Loudeac | B67: LCB (Loudeac) | C67: 1 LOT A
A69: VPSP Samu | B69: 22 (Siège) | C69: 1 LOT A
A70: VPSP Armor | C70: 1 LOT A
A71: VPSP Le Braz
...

Sheet 43
B1: N° de Semaine | J1: Du | N1: Au | V1: Membre AGO | Z1: Membre VD
B2: ='Calendrier AGO'!A21 -> 43 | J2: ='Calendrier AGO'!B21 -> 46314 | N2: ='Calendrier AGO'!C21 -> 46321 | V2: ='Calendrier AGO'!D21 -> Kevin Robin | Z2: ='Calendrier AGO'!E21 -> Michel
A4: Antenne | B4: Lundi | F4: Mardi | J4: Mercredi | N4: Jeudi | R4: Vendredi | V4: Samedi | Z4: Dimanche
B5: DPS | C5: Inscript. | F5: DPS | G5: Inscript. | J5: DPS | K5: Inscript. | N5: DPS | O5: Inscript. | R5: DPS | S5: Inscript. | V5: DPS | W5: Inscript. | Z5: DPS | AA5: Inscript.
C6: Nb | D6: De | E6: Tl | G6: Nb | H6: De | I6: Tl | K6: Nb | L6: De | M6: Tl | O6: Nb | P6: De | Q6: Tl | S6: Nb | T6: De | U6: Tl | W6: Nb | X6: De | Y6: Tl | AA6: Nb | AB6: De | AC6: Tl
A7: LNP (Lannion)
A10: PDG (Guingamp)
A13: PPL (Paimpol)
A16: STB (Saint Brieuc)
A19: PLR (Plérin)
A22: LPP (Lamballe)
A25: BRC (Broons)
A28: PDN (Dinan)
A31: QTN (Quintin)
A34: LCB (Loudeac)
A37: 22 (Siège)
A42: Indicatif | B42: Antenne | F42: Remarques | G42: Lundi | K42: Mardi | O42: Mercredi | S42: Jeudi | W42: Vendredi | AE42: Samedi | AG42: Dimanche
A44: VPSP1 Lannion | B44: LNP (Lannion) | C44: 1 LOT A
A45: PSM1 Lannion | C45: 1 LOT A + 1 C
A46: VTU-TP1 Lannion | C46: 1 LOT A + 1 C
A47: VL2 Lannion | C47: 1 LOT A + 1 C
A48: VLHR Lannion
A49: VPSP XX | B49: Paimpol (PPL)
A51: VPSP Vally | B51: PDG (Guingamp) | C51: 1 LOT A
A52: VL PABU
A53: VTP LANRODEC | C53: 1 LOT A + 1 C
A54: VPSP GOUEDIC | B54: STB (Saint Brieuc) | C54: 1 LOT A
A55: PSMA GRIFFON | C55: 1 LOT A + 1 C
A56: VPSP Rohanne'ch | B56: PLR (Plérin) | C56: 1 LOT A
A57: PSMA Guilloux | C57: 1 LOT A + 1 C
A58: VPSP 1 LAMBALLE | B58: LPP (Lamballe) | C58: 1 LOT A
A59: VTU-TP GRIFFON | C59: 1 LOT A + 1 C
A60: VTP CENTAURE
A61: VPSP X | B61: BRC (Broons) | C61: 1 LOT A
A63: VPSP 1 SAINT SAUVEUR | B63: PDN (Dinan) | C63: 1 LOT A
A65: VPSP XXX | B65: QTN (Quintin)
A67: VTUTP Loudeac | B67: LCB (Loudeac) | C67: 1 LOT A
A69: VPSP Samu | B69: 22 (Siège) | C69: 1 LOT A
A70: VPSP Armor | C70: 1 LOT A
A71: VPSP Le Braz
...

Sheet 44
B1: N° de Semaine | J1: Du | N1: Au | V1: Membre AGO | Z1: Membre VD
B2: ='Calendrier AGO'!A22 -> 44 | J2: ='Calendrier AGO'!B22 -> 46321 | N2: ='Calendrier AGO'!C22 -> 46328 | V2: ='Calendrier AGO'!D22 -> Marc-Olivier | Z2: ='Calendrier AGO'!E22 -> Adrien
A4: Antenne | B4: Lundi | F4: Mardi | J4: Mercredi | N4: Jeudi | R4: Vendredi | V4: Samedi | Z4: Dimanche
B5: DPS | C5: Inscript. | F5: DPS | G5: Inscript. | J5: DPS | K5: Inscript. | N5: DPS | O5: Inscript. | R5: DPS | S5: Inscript. | V5: DPS | W5: Inscript. | Z5: DPS | AA5: Inscript.
C6: Nb | D6: De | E6: Tl | G6: Nb | H6: De | I6: Tl | K6: Nb | L6: De | M6: Tl | O6: Nb | P6: De | Q6: Tl | S6: Nb | T6: De | U6: Tl | W6: Nb | X6: De | Y6: Tl | AA6: Nb | AB6: De | AC6: Tl
A7: LNP (Lannion)
A10: PDG (Guingamp)
A13: PPL (Paimpol)
A16: STB (Saint Brieuc)
A19: PLR (Plérin)
A22: LPP (Lamballe)
A25: BRC (Broons)
A28: PDN (Dinan)
A31: QTN (Quintin)
A34: LCB (Loudeac)
A37: 22 (Siège)
A42: Indicatif | B42: Antenne | F42: Remarques | G42: Lundi | K42: Mardi | O42: Mercredi | S42: Jeudi | W42: Vendredi | AE42: Samedi | AG42: Dimanche
A44: VPSP1 Lannion | B44: LNP (Lannion) | C44: 1 LOT A
A45: PSM1 Lannion | C45: 1 LOT A + 1 C
A46: VTU-TP1 Lannion | C46: 1 LOT A + 1 C
A47: VL2 Lannion | C47: 1 LOT A + 1 C
A48: VLHR Lannion
A49: VPSP XX | B49: Paimpol (PPL)
A51: VPSP Vally | B51: PDG (Guingamp) | C51: 1 LOT A
A52: VL PABU
A53: VTP LANRODEC | C53: 1 LOT A + 1 C
A54: VPSP GOUEDIC | B54: STB (Saint Brieuc) | C54: 1 LOT A
A55: PSMA GRIFFON | C55: 1 LOT A + 1 C
A56: VPSP Rohanne'ch | B56: PLR (Plérin) | C56: 1 LOT A
A57: PSMA Guilloux | C57: 1 LOT A + 1 C
A58: VPSP 1 LAMBALLE | B58: LPP (Lamballe) | C58: 1 LOT A
A59: VTU-TP GRIFFON | C59: 1 LOT A + 1 C
A60: VTP CENTAURE
A61: VPSP X | B61: BRC (Broons) | C61: 1 LOT A
A63: VPSP 1 SAINT SAUVEUR | B63: PDN (Dinan) | C63: 1 LOT A
A65: VPSP XXX | B65: QTN (Quintin)
A67: VTUTP Loudeac | B67: LCB (Loudeac) | C67: 1 LOT A
A69: VPSP Samu | B69: 22 (Siège) | C69: 1 LOT A
A70: VPSP Armor | C70: 1 LOT A
A71: VPSP Le Braz
...

Sheet 45
B1: N° de Semaine | J1: Du | N1: Au | V1: Membre AGO | Z1: Membre VD
B2: ='Calendrier AGO'!A23 -> 45 | J2: ='Calendrier AGO'!B23 -> 46328 | N2: ='Calendrier AGO'!C23 -> 46335 | V2: ='Calendrier AGO'!D23 -> Flavie Duval | Z2: ='Calendrier AGO'!E23 -> Nicolas
A4: Antenne | B4: Lundi | F4: Mardi | J4: Mercredi | N4: Jeudi | R4: Vendredi | V4: Samedi | Z4: Dimanche
B5: DPS | C5: Inscript. | F5: DPS | G5: Inscript. | J5: DPS | K5: Inscript. | N5: DPS | O5: Inscript. | R5: DPS | S5: Inscript. | V5: DPS | W5: Inscript. | Z5: DPS | AA5: Inscript.
C6: Nb | D6: De | E6: Tl | G6: Nb | H6: De | I6: Tl | K6: Nb | L6: De | M6: Tl | O6: Nb | P6: De | Q6: Tl | S6: Nb | T6: De | U6: Tl | W6: Nb | X6: De | Y6: Tl | AA6: Nb | AB6: De | AC6: Tl
A7: LNP (Lannion)
A10: PDG (Guingamp)
A13: PPL (Paimpol)
A16: STB (Saint Brieuc)
A19: PLR (Plérin)
A22: LPP (Lamballe)
A25: BRC (Broons)
A28: PDN (Dinan)
A31: QTN (Quintin)
A34: LCB (Loudeac)
A37: 22 (Siège)
A42: Indicatif | B42: Antenne | F42: Remarques | G42: Lundi | K42: Mardi | O42: Mercredi | S42: Jeudi | W42: Vendredi | AE42: Samedi | AG42: Dimanche
A44: VPSP1 Lannion | B44: LNP (Lannion) | C44: 1 LOT A
A45: PSM1 Lannion | C45: 1 LOT A + 1 C
A46: VTU-TP1 Lannion | C46: 1 LOT A + 1 C
A47: VL2 Lannion | C47: 1 LOT A + 1 C
A48: VLHR Lannion
A49: VPSP XX | B49: Paimpol (PPL)
A51: VPSP Vally | B51: PDG (Guingamp) | C51: 1 LOT A
A52: VL PABU
A53: VTP LANRODEC | C53: 1 LOT A + 1 C
A54: VPSP GOUEDIC | B54: STB (Saint Brieuc) | C54: 1 LOT A
A55: PSMA GRIFFON | C55: 1 LOT A + 1 C
A56: VPSP Rohanne'ch | B56: PLR (Plérin) | C56: 1 LOT A
A57: PSMA Guilloux | C57: 1 LOT A + 1 C
A58: VPSP 1 LAMBALLE | B58: LPP (Lamballe) | C58: 1 LOT A
A59: VTU-TP GRIFFON | C59: 1 LOT A + 1 C
A60: VTP CENTAURE
A61: VPSP X | B61: BRC (Broons) | C61: 1 LOT A
A63: VPSP 1 SAINT SAUVEUR | B63: PDN (Dinan) | C63: 1 LOT A
A65: VPSP XXX | B65: QTN (Quintin)
A67: VTUTP Loudeac | B67: LCB (Loudeac) | C67: 1 LOT A
A69: VPSP Samu | B69: 22 (Siège) | C69: 1 LOT A
A70: VPSP Armor | C70: 1 LOT A
A71: VPSP Le Braz
...

Sheet 46
B1: N° de Semaine | J1: Du | N1: Au | V1: Membre AGO | Z1: Membre VD
B2: ='Calendrier AGO'!A24 -> 46 | J2: ='Calendrier AGO'!B24 -> 46335 | N2: ='Calendrier AGO'!C24 -> 46342 | V2: ='Calendrier AGO'!D24 -> Steven Troel | Z2: ='Calendrier AGO'!E24 -> Laetitia
A4: Antenne | B4: Lundi | F4: Mardi | J4: Mercredi | N4: Jeudi | R4: Vendredi | V4: Samedi | Z4: Dimanche
B5: DPS | C5: Inscript. | F5: DPS | G5: Inscript. | J5: DPS | K5: Inscript. | N5: DPS | O5: Inscript. | R5: DPS | S5: Inscript. | V5: DPS | W5: Inscript. | Z5: DPS | AA5: Inscript.
C6: Nb | D6: De | E6: Tl | G6: Nb | H6: De | I6: Tl | K6: Nb | L6: De | M6: Tl | O6: Nb | P6: De | Q6: Tl | S6: Nb | T6: De | U6: Tl | W6: Nb | X6: De | Y6: Tl | AA6: Nb | AB6: De | AC6: Tl
A7: LNP (Lannion)
A10: PDG (Guingamp)
A13: PPL (Paimpol)
A16: STB (Saint Brieuc)
A19: PLR (Plérin)
A22: LPP (Lamballe)
A25: BRC (Broons)
A28: PDN (Dinan)
A31: QTN (Quintin)
A34: LCB (Loudeac)
A37: 22 (Siège)
A42: Indicatif | B42: Antenne | F42: Remarques | G42: Lundi | K42: Mardi | O42: Mercredi | S42: Jeudi | W42: Vendredi | AE42: Samedi | AG42: Dimanche
A44: VPSP1 Lannion | B44: LNP (Lannion) | C44: 1 LOT A
A45: PSM1 Lannion | C45: 1 LOT A + 1 C
A46: VTU-TP1 Lannion | C46: 1 LOT A + 1 C
A47: VL2 Lannion | C47: 1 LOT A + 1 C
A48: VLHR Lannion
A49: VPSP XX | B49: Paimpol (PPL)
A51: VPSP Vally | B51: PDG (Guingamp) | C51: 1 LOT A
A52: VL PABU
A53: VTP LANRODEC | C53: 1 LOT A + 1 C
A54: VPSP GOUEDIC | B54: STB (Saint Brieuc) | C54: 1 LOT A
A55: PSMA GRIFFON | C55: 1 LOT A + 1 C
A56: VPSP Rohanne'ch | B56: PLR (Plérin) | C56: 1 LOT A
A57: PSMA Guilloux | C57: 1 LOT A + 1 C
A58: VPSP 1 LAMBALLE | B58: LPP (Lamballe) | C58: 1 LOT A
A59: VTU-TP GRIFFON | C59: 1 LOT A + 1 C
A60: VTP CENTAURE
A61: VPSP X | B61: BRC (Broons) | C61: 1 LOT A
A63: VPSP 1 SAINT SAUVEUR | B63: PDN (Dinan) | C63: 1 LOT A
A65: VPSP XXX | B65: QTN (Quintin)
A67: VTUTP Loudeac | B67: LCB (Loudeac) | C67: 1 LOT A
A69: VPSP Samu | B69: 22 (Siège) | C69: 1 LOT A
A70: VPSP Armor | C70: 1 LOT A
A71: VPSP Le Braz
...

Sheet 47
B1: N° de Semaine | J1: Du | N1: Au | V1: Membre AGO | Z1: Membre VD
B2: ='Calendrier AGO'!A25 -> 47 | J2: ='Calendrier AGO'!B25 -> 46342 | N2: ='Calendrier AGO'!C25 -> 46349 | V2: ='Calendrier AGO'!D25 -> Louise Argaud | Z2: ='Calendrier AGO'!E25 -> Michel
A4: Antenne | B4: Lundi | F4: Mardi | J4: Mercredi | N4: Jeudi | R4: Vendredi | V4: Samedi | Z4: Dimanche
B5: DPS | C5: Inscript. | F5: DPS | G5: Inscript. | J5: DPS | K5: Inscript. | N5: DPS | O5: Inscript. | R5: DPS | S5: Inscript. | V5: DPS | W5: Inscript. | Z5: DPS | AA5: Inscript.
C6: Nb | D6: De | E6: Tl | G6: Nb | H6: De | I6: Tl | K6: Nb | L6: De | M6: Tl | O6: Nb | P6: De | Q6: Tl | S6: Nb | T6: De | U6: Tl | W6: Nb | X6: De | Y6: Tl | AA6: Nb | AB6: De | AC6: Tl
A7: LNP (Lannion)
A10: PDG (Guingamp)
A13: PPL (Paimpol)
A16: STB (Saint Brieuc)
A19: PLR (Plérin)
A22: LPP (Lamballe)
A25: BRC (Broons)
A28: PDN (Dinan)
A31: QTN (Quintin)
A34: LCB (Loudeac)
A37: 22 (Siège)
A42: Indicatif | B42: Antenne | F42: Remarques | G42: Lundi | K42: Mardi | O42: Mercredi | S42: Jeudi | W42: Vendredi | AE42: Samedi | AG42: Dimanche
A44: VPSP1 Lannion | B44: LNP (Lannion) | C44: 1 LOT A
A45: PSM1 Lannion | C45: 1 LOT A + 1 C
A46: VTU-TP1 Lannion | C46: 1 LOT A + 1 C
A47: VL2 Lannion | C47: 1 LOT A + 1 C
A48: VLHR Lannion
A49: VPSP XX | B49: Paimpol (PPL)
A51: VPSP Vally | B51: PDG (Guingamp) | C51: 1 LOT A
A52: VL PABU
A53: VTP LANRODEC | C53: 1 LOT A + 1 C
A54: VPSP GOUEDIC | B54: STB (Saint Brieuc) | C54: 1 LOT A
A55: PSMA GRIFFON | C55: 1 LOT A + 1 C
A56: VPSP Rohanne'ch | B56: PLR (Plérin) | C56: 1 LOT A
A57: PSMA Guilloux | C57: 1 LOT A + 1 C
A58: VPSP 1 LAMBALLE | B58: LPP (Lamballe) | C58: 1 LOT A
A59: VTU-TP GRIFFON | C59: 1 LOT A + 1 C
A60: VTP CENTAURE
A61: VPSP X | B61: BRC (Broons) | C61: 1 LOT A
A63: VPSP 1 SAINT SAUVEUR | B63: PDN (Dinan) | C63: 1 LOT A
A65: VPSP XXX | B65: QTN (Quintin)
A67: VTUTP Loudeac | B67: LCB (Loudeac) | C67: 1 LOT A
A69: VPSP Samu | B69: 22 (Siège) | C69: 1 LOT A
A70: VPSP Armor | C70: 1 LOT A
A71: VPSP Le Braz
...

Sheet 48
B1: N° de Semaine | J1: Du | N1: Au | V1: Membre AGO | Z1: Membre VD
B2: ='Calendrier AGO'!A26 -> 48 | J2: ='Calendrier AGO'!B26 -> 46349 | N2: ='Calendrier AGO'!C26 -> 46356 | V2: ='Calendrier AGO'!D26 -> Laurine Gérard | Z2: ='Calendrier AGO'!E26 -> Adrien
A4: Antenne | B4: Lundi | F4: Mardi | J4: Mercredi | N4: Jeudi | R4: Vendredi | V4: Samedi | Z4: Dimanche
B5: DPS | C5: Inscript. | F5: DPS | G5: Inscript. | J5: DPS | K5: Inscript. | N5: DPS | O5: Inscript. | R5: DPS | S5: Inscript. | V5: DPS | W5: Inscript. | Z5: DPS | AA5: Inscript.
C6: Nb | D6: De | E6: Tl | G6: Nb | H6: De | I6: Tl | K6: Nb | L6: De | M6: Tl | O6: Nb | P6: De | Q6: Tl | S6: Nb | T6: De | U6: Tl | W6: Nb | X6: De | Y6: Tl | AA6: Nb | AB6: De | AC6: Tl
A7: LNP (Lannion)
A10: PDG (Guingamp)
A13: PPL (Paimpol)
A16: STB (Saint Brieuc)
A19: PLR (Plérin)
A22: LPP (Lamballe)
A25: BRC (Broons)
A28: PDN (Dinan)
A31: QTN (Quintin)
A34: LCB (Loudeac)
A37: 22 (Siège)
A42: Indicatif | B42: Antenne | F42: Remarques | G42: Lundi | K42: Mardi | O42: Mercredi | S42: Jeudi | W42: Vendredi | AE42: Samedi | AG42: Dimanche
A44: VPSP1 Lannion | B44: LNP (Lannion) | C44: 1 LOT A
A45: PSM1 Lannion | C45: 1 LOT A + 1 C
A46: VTU-TP1 Lannion | C46: 1 LOT A + 1 C
A47: VL2 Lannion | C47: 1 LOT A + 1 C
A48: VLHR Lannion
A49: VPSP XX | B49: Paimpol (PPL)
A51: VPSP Vally | B51: PDG (Guingamp) | C51: 1 LOT A
A52: VL PABU
A53: VTP LANRODEC | C53: 1 LOT A + 1 C
A54: VPSP GOUEDIC | B54: STB (Saint Brieuc) | C54: 1 LOT A
A55: PSMA GRIFFON | C55: 1 LOT A + 1 C
A56: VPSP Rohanne'ch | B56: PLR (Plérin) | C56: 1 LOT A
A57: PSMA Guilloux | C57: 1 LOT A + 1 C
A58: VPSP 1 LAMBALLE | B58: LPP (Lamballe) | C58: 1 LOT A
A59: VTU-TP GRIFFON | C59: 1 LOT A + 1 C
A60: VTP CENTAURE
A61: VPSP X | B61: BRC (Broons) | C61: 1 LOT A
A63: VPSP 1 SAINT SAUVEUR | B63: PDN (Dinan) | C63: 1 LOT A
A65: VPSP XXX | B65: QTN (Quintin)
A67: VTUTP Loudeac | B67: LCB (Loudeac) | C67: 1 LOT A
A69: VPSP Samu | B69: 22 (Siège) | C69: 1 LOT A
A70: VPSP Armor | C70: 1 LOT A
A71: VPSP Le Braz
...

Sheet 49
B1: N° de Semaine | J1: Du | N1: Au | V1: Membre AGO | Z1: Membre VD
B2: ='Calendrier AGO'!A27 -> 49 | J2: ='Calendrier AGO'!B27 -> 46356 | N2: ='Calendrier AGO'!C27 -> 46363 | V2: ='Calendrier AGO'!D27 -> Kevin Robin | Z2: ='Calendrier AGO'!E27 -> Nicolas
A4: Antenne | B4: Lundi | F4: Mardi | J4: Mercredi | N4: Jeudi | R4: Vendredi | V4: Samedi | Z4: Dimanche
B5: DPS | C5: Inscript. | F5: DPS | G5: Inscript. | J5: DPS | K5: Inscript. | N5: DPS | O5: Inscript. | R5: DPS | S5: Inscript. | V5: DPS | W5: Inscript. | Z5: DPS | AA5: Inscript.
C6: Nb | D6: De | E6: Tl | G6: Nb | H6: De | I6: Tl | K6: Nb | L6: De | M6: Tl | O6: Nb | P6: De | Q6: Tl | S6: Nb | T6: De | U6: Tl | W6: Nb | X6: De | Y6: Tl | AA6: Nb | AB6: De | AC6: Tl
A7: LNP (Lannion)
A10: PDG (Guingamp)
A13: PPL (Paimpol)
A16: STB (Saint Brieuc)
A19: PLR (Plérin)
A22: LPP (Lamballe)
A25: BRC (Broons)
A28: PDN (Dinan)
A31: QTN (Quintin)
A34: LCB (Loudeac)
A37: 22 (Siège)
A42: Indicatif | B42: Antenne | F42: Remarques | G42: Lundi | K42: Mardi | O42: Mercredi | S42: Jeudi | W42: Vendredi | AE42: Samedi | AG42: Dimanche
A44: VPSP1 Lannion | B44: LNP (Lannion) | C44: 1 LOT A
A45: PSM1 Lannion | C45: 1 LOT A + 1 C
A46: VTU-TP1 Lannion | C46: 1 LOT A + 1 C
A47: VL2 Lannion | C47: 1 LOT A + 1 C
A48: VLHR Lannion
A49: VPSP XX | B49: Paimpol (PPL)
A51: VPSP Vally | B51: PDG (Guingamp) | C51: 1 LOT A
A52: VL PABU
A53: VTP LANRODEC | C53: 1 LOT A + 1 C
A54: VPSP GOUEDIC | B54: STB (Saint Brieuc) | C54: 1 LOT A
A55: PSMA GRIFFON | C55: 1 LOT A + 1 C
A56: VPSP Rohanne'ch | B56: PLR (Plérin) | C56: 1 LOT A
A57: PSMA Guilloux | C57: 1 LOT A + 1 C
A58: VPSP 1 LAMBALLE | B58: LPP (Lamballe) | C58: 1 LOT A
A59: VTU-TP GRIFFON | C59: 1 LOT A + 1 C
A60: VTP CENTAURE
A61: VPSP X | B61: BRC (Broons) | C61: 1 LOT A
A63: VPSP 1 SAINT SAUVEUR | B63: PDN (Dinan) | C63: 1 LOT A
A65: VPSP XXX | B65: QTN (Quintin)
A67: VTUTP Loudeac | B67: LCB (Loudeac) | C67: 1 LOT A
A69: VPSP Samu | B69: 22 (Siège) | C69: 1 LOT A
A70: VPSP Armor | C70: 1 LOT A
A71: VPSP Le Braz
...

Sheet 50
B1: N° de Semaine | J1: Du | N1: Au | V1: Membre AGO | Z1: Membre VD
B2: ='Calendrier AGO'!A28 -> 50 | J2: ='Calendrier AGO'!B28 -> 46363 | N2: ='Calendrier AGO'!C28 -> 46370 | V2: ='Calendrier AGO'!D28 -> Nicolas Le Bail | Z2: ='Calendrier AGO'!E28 -> Laetitia
A4: Antenne | B4: Lundi | F4: Mardi | J4: Mercredi | N4: Jeudi | R4: Vendredi | V4: Samedi | Z4: Dimanche
B5: DPS | C5: Inscript. | F5: DPS | G5: Inscript. | J5: DPS | K5: Inscript. | N5: DPS | O5: Inscript. | R5: DPS | S5: Inscript. | V5: DPS | W5: Inscript. | Z5: DPS | AA5: Inscript.
C6: Nb | D6: De | E6: Tl | G6: Nb | H6: De | I6: Tl | K6: Nb | L6: De | M6: Tl | O6: Nb | P6: De | Q6: Tl | S6: Nb | T6: De | U6: Tl | W6: Nb | X6: De | Y6: Tl | AA6: Nb | AB6: De | AC6: Tl
A7: LNP (Lannion)
A10: PDG (Guingamp)
A13: PPL (Paimpol)
A16: STB (Saint Brieuc)
A19: PLR (Plérin)
A22: LPP (Lamballe)
A25: BRC (Broons)
A28: PDN (Dinan)
A31: QTN (Quintin)
A34: LCB (Loudeac)
A37: 22 (Siège)
A42: Indicatif | B42: Antenne | F42: Remarques | G42: Lundi | K42: Mardi | O42: Mercredi | S42: Jeudi | W42: Vendredi | AE42: Samedi | AG42: Dimanche
A44: VPSP1 Lannion | B44: LNP (Lannion) | C44: 1 LOT A
A45: PSM1 Lannion | C45: 1 LOT A + 1 C
A46: VTU-TP1 Lannion | C46: 1 LOT A + 1 C
A47: VL2 Lannion | C47: 1 LOT A + 1 C
A48: VLHR Lannion
A49: VPSP XX | B49: Paimpol (PPL)
A51: VPSP Vally | B51: PDG (Guingamp) | C51: 1 LOT A
A52: VL PABU
A53: VTP LANRODEC | C53: 1 LOT A + 1 C
A54: VPSP GOUEDIC | B54: STB (Saint Brieuc) | C54: 1 LOT A
A55: PSMA GRIFFON | C55: 1 LOT A + 1 C
A56: VPSP Rohanne'ch | B56: PLR (Plérin) | C56: 1 LOT A
